<?xml version="1.0" encoding="utf-8"?>
<!-- This URDF was automatically created by SolidWorks to URDF Exporter! Originally created by Stephen Brawner (brawner@gmail.com) 
     Commit Version: 1.6.0-4-g7f85cfe  Build Version: 1.6.7995.38578
     For more information, please see http://wiki.ros.org/sw_urdf_exporter -->
<robot name="mark_one_arm" xmlns:xacro="http://www.ros.org/wiki/xacro">
  <!-- create link fixed to the "world" -->
  <link name="world" />
  <link name="base_link">
    <inertial>
      <origin xyz="-0.038112 1.1649E-05 -0.051288" rpy="0 0 0" />
      <mass value="1.7609" />
      <inertia
        ixx="0.013987"
        ixy="4.568E-06"
        ixz="-0.0017308"
        iyy="0.017262"
        iyz="-1.5817E-06"
        izz="0.0096448" />
    </inertial>
    <visual>
      <origin xyz="0 0 0" rpy="0 0 0" />
      <geometry>
        <mesh filename="package://mark_one_arm_description/meshes/base_link.STL" />
          <!-- filename="package://AMH19_Mark1_Complete_URDF/meshes/base_link.STL" />  -->
      </geometry>
      <material name="">
        <color rgba="0.19608 0.58824 1 1" />
      </material>
    </visual>
    <collision>
      <origin xyz="0 0 0" rpy="0 0 0" />
      <geometry>
        <mesh filename="package://mark_one_arm_description/meshes/base_link.STL" />
      </geometry>
    </collision>
  </link>
  <joint name="base_joint" type="fixed">
    <parent link="world"/>
    <child link="base_link"/>
    <origin rpy="0.0 0.0 0.0" xyz="0.0 0.0 0.0"/>
  </joint>
  <link name="Link_1">
    <inertial>
      <origin xyz="0.00065581 -0.0064466 0.026051" rpy="0 0 0" />
      <mass value="0.42083" />
      <inertia
        ixx="0.0010943"
        ixy="-3.8989E-08"
        ixz="6.9374E-08"
        iyy="0.00108"
        iyz="3.3023E-05"
        izz="0.0019753" />
    </inertial>
    <visual>
      <origin xyz="0 0 0" rpy="0 0 0" />
      <geometry>
        <mesh filename="package://mark_one_arm_description/meshes/Link_1.STL" />
      </geometry>
      <material name="">
        <color rgba="0.19608 0.58824 1 1" />
      </material>
    </visual>
    <collision>
      <origin xyz="0 0 0" rpy="0 0 0" />
      <geometry>
        <mesh filename="package://mark_one_arm_description/meshes/Link_1.STL" />
      </geometry>
    </collision>
  </link>
  <joint name="Joint_1" type="revolute">
    <origin xyz="0.0005 0 0.0675" rpy="0 0 3.1416" />
    <parent link="base_link" />
    <child link="Link_1" />
    <axis xyz="0 0 -1" />
    <limit lower="-${pi}" upper="${pi}" effort="1" velocity="3" />
  </joint>
  <link name="Link_2">
    <inertial>
      <origin xyz="-9.8731E-05 0.024339 0.10001" rpy="0 0 0" />
      <mass value="0.16055" />
      <inertia
        ixx="0.00081029"
        ixy="-5.0894E-08"
        ixz="2.4508E-08"
        iyy="0.00082113"
        iyz="-1.246E-08"
        izz="5.324E-05" />
    </inertial>
    <visual>
      <origin xyz="0 0 0" rpy="0 0 0" />
      <geometry>
        <mesh filename="package://mark_one_arm_description/meshes/Link_2.STL" />
      </geometry>
      <material name="">
        <color rgba="0.19608 0.58824 1 1" />
      </material>
    </visual>
    <collision>
      <origin xyz="0 0 0" rpy="0 0 0" />
      <geometry>
        <mesh filename="package://mark_one_arm_description/meshes/Link_2.STL" />
      </geometry>
    </collision>
  </link>
  <joint name="Joint_2" type="revolute">
    <origin xyz="0.0005 -0.00615 0.0875" rpy="0 0 0" />
    <parent link="Link_1" />
    <child link="Link_2" />
    <axis xyz="0 1 0" />
    <limit lower="-${pi/2}" upper="${pi/2}" effort="1" velocity="3" />
  </joint>
  <link name="Link_3">
    <inertial>
      <origin xyz="-0.077349 -0.024767 4.4737E-05" rpy="0 0 0" />
      <mass value="0.22178" />
      <inertia
        ixx="4.9456E-05"
        ixy="3.1264E-06"
        ixz="1.5521E-06"
        iyy="0.00038278"
        iyz="-3.4186E-08"
        izz="0.00037292" />
    </inertial>
    <visual>
      <origin xyz="0 0 0" rpy="0 0 0" />
      <geometry>
        <mesh filename="package://mark_one_arm_description/meshes/Link_3.STL" />
      </geometry>
      <material name="">
        <color rgba="0.19608 0.58824 1 1" />
      </material>
    </visual>
    <collision>
      <origin xyz="0 0 0" rpy="0 0 0" />
      <geometry>
        <mesh filename="package://mark_one_arm_description/meshes/Link_3.STL" />
      </geometry>
    </collision>
  </link>
  <joint name="Joint_3" type="revolute">
    <origin xyz="0 0 0.20005" rpy="0 0 0" />
    <parent link="Link_2" />
    <child link="Link_3" />
    <axis xyz="0 1 0" />
    <limit lower="-${pi/2}" upper="${pi/2}" effort="1" velocity="3" />
  </joint>
  <link name="Link_4">
    <inertial>
      <origin xyz="-0.030101 0.0058914 -0.0054388" rpy="0 0 0" />
      <mass value="0.10316" />
      <inertia
        ixx="1.8487E-05"
        ixy="2.0257E-07"
        ixz="-1.3162E-08"
        iyy="2.6443E-05"
        iyz="2.9228E-08"
        izz="2.8243E-05" />
    </inertial>
    <visual>
      <origin xyz="0 0 0" rpy="0 0 0" />
      <geometry>
        <mesh filename="package://mark_one_arm_description/meshes/Link_4.STL" />
      </geometry>
      <material name="">
        <color rgba="0.19608 0.58824 1 1" />
      </material>
    </visual>
    <collision>
      <origin xyz="0 0 0" rpy="0 0 0" />
      <geometry>
        <mesh filename="package://mark_one_arm_description/meshes/Link_4.STL" />
      </geometry>
    </collision>
  </link>
  <joint name="Joint_4" type="revolute">
    <origin xyz="-0.15685 -0.0252 0.0054" rpy="0 0 0" />
    <parent link="Link_3" />
    <child link="Link_4" />
    <axis xyz="1 0 0" />
    <limit lower="-${pi}" upper="${pi}" effort="0.118" velocity="4.2" />
  </joint>
  <link name="Link_5">
    <inertial>
      <origin xyz="-0.04751 0.01529 -0.0019025" rpy="0 0 0" />
      <mass value="0.016216" />
      <inertia
        ixx="1.635E-06"
        ixy="2.3499E-10"
        ixz="-1.1461E-06"
        iyy="2.7644E-05"
        iyz="-2.9451E-09"
        izz="2.8764E-05" />
    </inertial>
    <visual>
      <origin xyz="0 0 0" rpy="0 0 0" />
      <geometry>
        <mesh filename="package://mark_one_arm_description/meshes/Link_5.STL" />
      </geometry>
      <material name="">
        <color rgba="0.19608 0.58824 1 1" />
      </material>
    </visual>
    <collision>
      <origin xyz="0 0 0" rpy="0 0 0" />
      <geometry>
        <mesh filename="package://mark_one_arm_description/meshes/Link_5.STL" />
      </geometry>
    </collision>
  </link>
  <joint name="Joint_5" type="revolute">
    <origin xyz="-0.03875 0.02745 -0.00545" rpy="0 0 0" />
    <parent link="Link_4" />
    <child link="Link_5" />
    <axis xyz="0 -1 0" />
    <limit lower="-${pi}" upper="${pi}" effort="0.118" velocity="4.2" />
  </joint>
</robot>