<?xml version="1.0" ?>
<!-- =================================================================================== -->
<!-- |    This document was autogenerated by xacro from differential_robot.urdf.xacro  | -->
<!-- |    EDITING THIS FILE BY HAND IS NOT RECOMMENDED                                 | -->
<!-- =================================================================================== -->
<robot name="differential_robot">
  <!-- Robot links section -->
  <link name="base_footprint"/>
  <link name="base_link">
    <inertial>
      <origin rpy="0.0 0.0 0.0" xyz="0.0 0.0 0.1"/>
      <mass value="5.0"/>
      <inertia ixx="0.6666666666666667" ixy="0.0" ixz="0.0" iyy="0.8666666666666667" iyz="0.0" izz="0.3333333333333334"/>
    </inertial>
    <visual>
      <geometry>
        <box size="0.6 0.4 0.2"/>
      </geometry>
      <origin rpy="0.0 0.0 0.0" xyz="0.0 0.0 0.1"/>
      <material name="green">
        <color rgba="0.0 0.5 0.0 1.0"/>
      </material>
    </visual>
  </link>
  <link name="right_wheel_link">
    <inertial>
      <origin rpy="1.5707963267948966 0.0 0.0" xyz="0.0 0.0 0.0"/>
      <mass value="1.0"/>
      <inertia ixx="0.010833333333333335" ixy="0.0" ixz="0.0" iyy="0.010833333333333335" iyz="0.0" izz="0.020000000000000004"/>
    </inertial>
    <visual>
      <geometry>
        <cylinder length="0.05" radius="0.1"/>
      </geometry>
      <origin rpy="1.5707963267948966 0.0 0.0" xyz="0.0 0.0 0.0"/>
      <material name="gray">
        <color rgba="0.5 0.5 0.5 1.0"/>
      </material>
    </visual>
  </link>
  <link name="left_wheel_link">
    <inertial>
      <origin rpy="1.5707963267948966 0.0 0.0" xyz="0.0 0.0 0.0"/>
      <mass value="1.0"/>
      <inertia ixx="0.010833333333333335" ixy="0.0" ixz="0.0" iyy="0.010833333333333335" iyz="0.0" izz="0.020000000000000004"/>
    </inertial>
    <visual>
      <geometry>
        <cylinder length="0.05" radius="0.1"/>
      </geometry>
      <origin rpy="1.5707963267948966 0.0 0.0" xyz="0.0 0.0 0.0"/>
      <material name="gray">
        <color rgba="0.5 0.5 0.5 1.0"/>
      </material>
    </visual>
  </link>
  <!-- <link name="right_wheel_link">
        <visual>
            <geometry>
                <cylinder radius="${wheel_radius}" length="${wheel_lenght}"/>
            </geometry>
            <origin xyz="0.0 0.0 0.0" rpy="${pi/2.0} 0.0 0.0"/>
            <material name="gray"/>
        </visual>
    </link>
    <link name="left_wheel_link">
        <visual>
            <geometry>
                <cylinder radius="${wheel_radius}" length="${wheel_lenght}"/>
            </geometry>
            <origin xyz="0.0 0.0 0.0" rpy="${pi/2.0} 0.0 0.0"/>
            <material name="gray"/>
        </visual>
    </link> -->
  <link name="caster_wheel_link">
    <inertial>
      <origin rpy="0.0 0.0 0.0" xyz="0.0 0.0 0.0"/>
      <mass value="0.5"/>
      <inertia ixx="0.0020000000000000005" ixy="0.0" ixz="0.0" iyy="0.0020000000000000005" iyz="0.0" izz="0.0020000000000000005"/>
    </inertial>
    <visual>
      <geometry>
        <sphere radius="0.05"/>
      </geometry>
      <origin rpy="0.0 0.0 0.0" xyz="0.0 0.0 0.0"/>
      <material name="gray">
        <color rgba="0.5 0.5 0.5 1.0"/>
      </material>
    </visual>
  </link>
  <!-- Robot joints section -->
  <joint name="base_joint" type="fixed">
    <parent link="base_footprint"/>
    <child link="base_link"/>
    <origin rpy="0.0 0.0 0.0" xyz="0.0 0.0 0.1"/>
  </joint>
  <joint name="base_right_wheel_joint" type="continuous">
    <parent link="base_link"/>
    <child link="right_wheel_link"/>
    <axis xyz="0 1 0"/>
    <origin rpy="0 0 0" xyz="-0.15 -0.225  0.0"/>
  </joint>
  <joint name="base_left_wheel_joint" type="continuous">
    <parent link="base_link"/>
    <child link="left_wheel_link"/>
    <axis xyz="0 1 0"/>
    <origin rpy="0 0 0" xyz="-0.15 0.225 0.0"/>
  </joint>
  <joint name="base_caster_wheel_joint" type="fixed">
    <parent link="base_link"/>
    <child link="caster_wheel_link"/>
    <origin rpy="0.0 0.0 0.0" xyz="0.19999999999999998 0.0 -0.05"/>
  </joint>
  
  <link name="camera_link">
    <visual>
      <inertial>
        <origin rpy="0.0 0.0 0.0" xyz="0.0 0.0 0.0"/>
        <mass value="0.1"/>
        <inertia ixx="2.166666666666667e-05" ixy="0.0" ixz="0.0" iyy="8.416666666666668e-05" iyz="0.0" izz="0.00010416666666666669"/>
      </inertial>
      <geometry>
        <box size="0.01 0.1 0.05"/>
      </geometry>
      <origin rpy="0.0 0.0 0.0" xyz="0.0 0.0 0.0"/>
      <material name='blue'>
        <color rgba="0.0 0.0 0.5 1.0"/>
      </material>
    </visual>
  </link>
  <!-- generate an optical frame 
      http://www.ros.org/reps/rep-0103.html#suffix-frames
      so that ros and opencv can operate on the camera frame correctly 
      -->
  <link name="camera_optical_link"/>
  <joint name="camera_optical_joint" type="fixed">
    <!-- these values have to be these values otherwise the gazebo camera
            image won't be aligned properly with the frame it is supposedly
            originating from -->
    <origin rpy="-1.5707963267948966 0 -1.5707963267948966" xyz="0 0 0"/>
    <parent link="camera_link"/>
    <child link="camera_optical_link"/>
  </joint>
  <joint name="base_camera_joint" type="fixed">
    <parent link="base_link"/>
    <child link="camera_link"/>
    <origin rpy="0.0 0.0 0.0" xyz="0.305 0.0 0.1"/>
  </joint>
</robot>
