<?xml version="1.0" encoding="UTF-8"?>

<robot name="my_tutor_robot">
    <material name="green">
        <color rgba="0.0 0.5 0.0 1.0"/>
    </material>

    <material name="grey">
        <color rgba="0.5 0.5 0.5 1.0"/>
    </material>

    <link name="base_footprint"/>
    
    <link name="base_link">
        <visual>
            <geometry>
                <box size="0.6 0.4 0.2"/>
            </geometry>
            <origin xyz="0.0 0.0 0.1" rpy="0.0 0.0 0.0"/>
            <material name="green"/>
        </visual>
    </link>
    <!-- <link name="second_link">
        <visual>
            <geometry>
                <cylinder radius="0.1" length="0.2"/>
            </geometry>
            <origin xyz="0.0 0.0 0.1" rpy="0.0 0.0 0.0"/>
            <material name="grey"/>
        </visual>
    </link>

    <link name="third_link">
        <visual>
            <origin xyz="0.0 0.0 0.05" rpy="0.0 0.0 0.0"/>
            <geometry>
                <box size="0.1 0.1 0.1"/>
            </geometry>
            <material name="green"/>
        </visual>
    </link> -->

    <link name="right_wheel_link">
        <visual>
            <origin xyz="0.0 0.0 0.0" rpy="1.57 0.0 0.0"/>
            <geometry>
                <cylinder radius="0.1" length="0.05"/>
            </geometry>
            <material name="grey"/>
        </visual>
    </link>
    <link name="left_wheel_link">
        <visual>
            <origin xyz="0.0 0.0 0.0" rpy="1.57 0.0 0.0"/>
            <geometry>
                <cylinder radius="0.1" length="0.05"/>
            </geometry>
            <material name="grey"/>
        </visual>
    </link>
    <link name="caster_wheel_link">
        <visual>
            <origin xyz="0.0 0.0 0.0" rpy="0.0 0.0 0.0"/>
            <geometry>
                <sphere radius="0.05"/>
            </geometry>
            <material name="grey"/>
        </visual>
    </link>

    <!-- <joint name="base_second_joint" type="revolute">
        <parent link="base_link"/>
        <child link="second_link"/>
        <axis xyz="0 0 1"/>
        <limit lower="-1.57" upper="1.57" effort="1.0" velocity="3.14"/>
        <origin xyz="0.0 0.0 0.2" rpy="0.0 0.0 0.0"/>
    </joint>
    <joint name="second_third_joint" type="prismatic">
        <parent link="second_link"/>
        <child link="third_link"/>
        <origin xyz="0.0 0.0 0.2" rpy="0.0 0.0 0.0"/>
        <axis xyz="0 0 1"/>
        <limit lower="0.0" upper="0.2" effort="1.0" velocity="0.1"/>
    </joint> -->
    <joint name="base_joint" type="fixed">
        <parent link="base_footprint"/>
        <child link="base_link"/>
        <origin xyz="0.0 0.0 0.1" rpy="0.0 0.0 0.0"/>
    </joint>
    
    <joint name="base_right_wheel_joint" type="continuous">
        <parent link="base_link"/>
        <child link="right_wheel_link"/>
        <origin xyz="-0.15 -0.225 0.0" rpy="0.0 0.0 0.0"/>
        <axis xyz="0 1 0"/>
    </joint>
    <joint name="base_left_wheel_joint" type="continuous">
        <parent link="base_link"/>
        <child link="left_wheel_link"/>
        <axis xyz="0 1 0"/>
        <origin xyz="-0.15 0.225 0" rpy="0 0 0"/>
    </joint>
    <joint name="base_caster_wheel_joint" type="fixed">
        <parent link="base_link"/>
        <child link="caster_wheel_link"/>
        <origin xyz="0.2 0.0 -0.05" rpy="0.0 0.0 0.0"/>
    </joint>
    
    
</robot>